package supersymmetry.common.metatileentities.multi.electric;

import gregtech.api.capability.impl.MultiblockRecipeLogic;
import gregtech.api.metatileentity.MetaTileEntity;
import gregtech.api.metatileentity.interfaces.IGregTechTileEntity;
import gregtech.api.metatileentity.multiblock.IMultiblockPart;
import gregtech.api.metatileentity.multiblock.RecipeMapMultiblockController;
import gregtech.api.pattern.BlockPattern;
import gregtech.api.pattern.FactoryBlockPattern;
import gregtech.client.renderer.ICubeRenderer;
import net.minecraft.util.ResourceLocation;
import org.jetbrains.annotations.NotNull;
import supersymmetry.api.metatileentity.multiblock.SuSyPredicates;
import supersymmetry.api.recipes.SuSyRecipeMaps;
import supersymmetry.common.blocks.BlockRocketAssemblerCasing;
import supersymmetry.common.blocks.SuSyBlocks;

public class MetaTileEntityRocketAssembler extends RecipeMapMultiblockController {

    public MetaTileEntityRocketAssembler(ResourceLocation metaTileEntityId) {
        super(metaTileEntityId, SuSyRecipeMaps.ROCKET_ASSEMBLER);
        this.recipeMapWorkable = new MultiblockRecipeLogic(this);
    }

    @Override
    protected @NotNull BlockPattern createStructurePattern() {
        return FactoryBlockPattern.start()
                .aisle("FFFFFFFFFFFFFFFFFFFFFFFFFFFFFFFFFFFFFFFFFFFFFFFFFFFFFFFFFFFFFFF").aisle("FFFFFFFFFFFFFFFFFFFFFFFFFFFFFFFFFFFFFFFFFFFFFFFFFFFFFFFFFFFFFFF").aisle("CCCCCCCCCCCCCCCCCCCCCCCCCCCCCCCCCCCCCCCCCCCCCCCCCCCCCCCCCCCCCCC").aisle("CCCCCCCCCCCCCCCCCCCCCCCCCCCCCCCCCCCCCCCCCCCCCCCCCCCCCCCCCCCCCCC").aisle("CCCCCCCCCCCCCCCCCCCCCCCCCCCCCCCCCCCCCCCCCCCCCCCCCCCCCCCCCCCCCCC").aisle("                                                               ").aisle("                                                               ").aisle("                                                               ").aisle("                                                               ").aisle("                                                               ").aisle("                                                               ").aisle("                                                               ").aisle("                                                               ").aisle("                                                               ").aisle("                                                               ").aisle("                                                               ")
                .aisle("FFFFFFFFFFFFFFFFFFFFFFFFFFFFFFFFFFFFFFFFFFFFFFFFFFFFFFFFFFFFFFF").aisle("FFFFFFFFFFFFFFFFFFFFFFFFFFFFFFFFFFFFFFFFFFFFFFFFFFFFFFFFFFFFFFF").aisle("CCCCCCCCCCCCCCCCCCCCCCCCCCCCCCCCCCCCCCCCCCCCCCCCCCCCCCCCCCCCCCC").aisle("CCCCCCCCCCCCCCCCCCCCCCCCCCCCCCCCCCCCCCCCCCCCCCCCCCCCCCCCCCCCCCC").aisle("CCCCCCCCCCCCCCCCCCCCCCCCCCCCCCCCCCCCCCCCCCCCCCCCCCCCCCCCCCCCCCC").aisle(" P   P   P   P   P   P   P   P   P   P   P   P   P   P   P   P ").aisle(" P   P   P   P   P   P   P   P   P   P   P   P   P   P   P   P ").aisle(" P   P   P   P   P   P   P   P   P   P   P   P   P   P   P   P ").aisle(" P   P   P   P   P   P   P   P   P   P   P   P   P   P   P   P ").aisle(" P   P   P   P   P   P   P   P   P   P   P   P   P   P   P   P ").aisle(" P   P   P   P   P   P   P   P   P   P   P   P   P   P   P   P ").aisle(" P   P   P   P   P   P   P   P   P   P   P   P   P   P   P   P ").aisle(" P   P   P   P   P   P   P   P   P   P   P   P   P   P   P   P ").aisle(" P   P   P   P   P   P   P   P   P   P   P   P   P   P   P   P ").aisle(" P   P   P   P   P   P   P   P   P   P   P   P   P   P   P   P ").aisle(" P   P   P   P   P   P   P   P   P   P   P   P   P   P   P   P ")
                .aisle("FFFFFFFFFFFFFFFFFFFFFFFFFFFFFFFFFFFFFFFFFFFFFFFFFFFFFFFFFFFFFFF").aisle("FFFFFFFFFFFFFFFFFFFFFFFFFFFFFFFFFFFFFFFFFFFFFFFFFFFFFFFFFFFFFFF").aisle("CCCCCCCCCCCCCCCCCCCCCCCCCCCCCCCCCCCCCCCCCCCCCCCCCCCCCCCCCCCCCCC").aisle("                                                               ").aisle("                                                               ").aisle("                                                               ").aisle("                                                               ").aisle("                                                               ").aisle("                                                               ").aisle("                                                               ").aisle("                                                               ").aisle("                                                               ").aisle("                                                               ").aisle("                                                               ").aisle("                                                               ").aisle(" P           P   P           P   P           P   P           P ")
                .aisle("FFFFFFFFFFFFFFFFFFFFFFFFFFFFFFFFFFFFFFFFFFFFFFFFFFFFFFFFFFFFFFF").aisle("FFFFFFFFFFFFFFFFFFFFFFFFFFFFFFFFFFFFFFFFFFFFFFFFFFFFFFFFFFFFFFF").aisle("CCCCCCCCCCCCCCCCCCCCCCCCCCCCCCCCCCCCCCCCCCCCCCCCCCCCCCCCCCCCCCC").aisle("                                                               ").aisle("                                                               ").aisle("                                                               ").aisle("                                                               ").aisle("                                                               ").aisle("                                                               ").aisle("                                                               ").aisle("                                                               ").aisle("                                                               ").aisle("                                                               ").aisle("                                                               ").aisle("                                                               ").aisle(" P           P   P           P   P           P   P           P ")
                .aisle("FFFFFFFFFFFFFFFFFFFFFFFFFFFFFFFFFFFFFFFFFFFFFFFFFFFFFFFFFFFFFFF").aisle("FFFFFFFFFFFFFFFFFFFFFFFFFFFFFFFFFFFFFFFFFFFFFFFFFFFFFFFFFFFFFFF").aisle("CCCCCCCCCCCCCCCCCCCCCCCCCCCCCCCCCCCCCCCCCCCCCCCCCCCCCCCCCCCCCCC").aisle("                                                               ").aisle("                                                               ").aisle("                                                               ").aisle("                                                               ").aisle("                                                               ").aisle("                                                               ").aisle("                                                               ").aisle("                                                               ").aisle("                                                               ").aisle("                                                               ").aisle("                                                               ").aisle("                                                               ").aisle(" P           P   P           P   P           P   P           P ")
                .aisle("FFFFFFFFFFFFFFFFFFFFFFFFFFFFFFFFFFFFFFFFFFFFFFFFFFFFFFFFFFFFFFF").aisle("FFFFFFFFFFFFFFFFFFFFFFFFFFFFFFFFFFFFFFFFFFFFFFFFFFFFFFFFFFFFFFF").aisle("CCCCCCCCCCCCCCCCCCCCCCCCCCCCCCCCCCCCCCCCCCCCCCCCCCCCCCCCCCCCCCC").aisle("                                                               ").aisle("                                                               ").aisle("                                                               ").aisle("                                                               ").aisle("                                                               ").aisle("                                                               ").aisle("                                                               ").aisle("                                                               ").aisle("                                                               ").aisle("                                                               ").aisle("                                                               ").aisle("BBBBBBBBBBBBBBBBBBBBBBBBBBBBBBBBBBBBBBBBBBBBBBBBBBBBBBBBBBBBBBB").aisle(" P           P   P           P   P           P   P           P ")
                .aisle("FFFFFFFFFFFFFFFFFFFFFFFFFFFFFFFFFFFFFFFFFFFFFFFFFFFFFFFFFFFFFFF").aisle("FFFFFFFFFFFFFFFFFFFFFFFFFFFFFFFFFFFFFFFFFFFFFFFFFFFFFFFFFFFFFFF").aisle("CCCCCCCCCCCCCCCCCCCCCCCCCCCCCCCCCCCCCCCCCCCCCCCCCCCCCCCCCCCCCCC").aisle("RRRRRRRRRRRRRRRRRRRRRRRRRRRRRRRRRRRRRRRRRRRRRRRRRRRRRRRRRRRRRRR").aisle("                                                               ").aisle("                                                               ").aisle("                                                               ").aisle("                                                               ").aisle("                                                               ").aisle("                                                               ").aisle("                                                               ").aisle("                                                               ").aisle("                                                               ").aisle("                                                               ").aisle("                                                               ").aisle(" P           P   P           P   P           P   P           P ")
                .aisle("                                                               ").aisle("                                                               ").aisle("                                                               ").aisle("RRRRRRRRRRRRRRRRRRRRRRRRRRRRRRRRRRRRRRRRRRRRRRRRRRRRRRRRRRRRRRR").aisle("                                                               ").aisle("                                                               ").aisle("                                                               ").aisle("                                                               ").aisle("                                                               ").aisle("                                                               ").aisle("                                                               ").aisle("                                                               ").aisle("                                                               ").aisle("                                                               ").aisle("                                                               ").aisle(" P           P   P           P   P           P   P           P ")
                .aisle("FFFFFFFFFFFFFFFFFFFFFFFFFFFFFFFFFFFFFFFFFFFFFFFFFFFFFFFFFFFFFFF").aisle("FFFFFFFFFFFFFFFFFFFFFFFFFFFFFFFFFFFFFFFFFFFFFFFFFFFFFFFFFFFFFFF").aisle("CCCCCCCCCCCCCCCCCCCCCCCCCCCCCCCCCCCCCCCCCCCCCCCCCCCCCCCCCCCCCCC").aisle("RRRRRRRRRRRRRRRRRRRRRRRRRRRRRRRRRRRRRRRRRRRRRRRRRRRRRRRRRRRRRRR").aisle("                                                               ").aisle("                                                               ").aisle("                                                               ").aisle("                                                               ").aisle("                                                               ").aisle("                                                               ").aisle("                                                               ").aisle("                                                               ").aisle("                                                               ").aisle("                                                               ").aisle("                                                               ").aisle(" P           P   P           P   P           P   P           P ")
                .aisle("FFFFFFFFFFFFFFFFFFFFFFFFFFFFFFFFFFFFFFFFFFFFFFFFFFFFFFFFFFFFFFF").aisle("FFFFFFFFFFFFFFFFFFFFFFFFFFFFFFFFFFFFFFFFFFFFFFFFFFFFFFFFFFFFFFF").aisle("CCCCCCCCCCCCCCCCCCCCCCCCCCCCCCCCCCCCCCCCCCCCCCCCCCCCCCCCCCCCCCC").aisle("                                                               ").aisle("                                                               ").aisle("                                                               ").aisle("                                                               ").aisle("                                                               ").aisle("                                                               ").aisle("                                                               ").aisle("                                                               ").aisle("                                                               ").aisle("                                                               ").aisle("                                                               ").aisle("BBBBBBBBBBBBBBBBBBBBBBBBBBBBBBBBBBBBBBBBBBBBBBBBBBBBBBBBBBBBBBB").aisle(" P           P   P           P   P           P   P           P ")
                .aisle("FFFFFFFFFFFFFFFFFFFFFFFFFFFFFFFFFFFFFFFFFFFFFFFFFFFFFFFFFFFFFFF").aisle("FFFFFFFFFFFFFFFFFFFFFFFFFFFFFFFFFFFFFFFFFFFFFFFFFFFFFFFFFFFFFFF").aisle("CCCCCCCCCCCCCCCCCCCCCCCCCCCCCCCCCCCCCCCCCCCCCCCCCCCCCCCCCCCCCCC").aisle("                                                               ").aisle("                                                               ").aisle("                                                               ").aisle("                                                               ").aisle("                                                               ").aisle("                                                               ").aisle("                                                               ").aisle("                                                               ").aisle("                                                               ").aisle("                                                               ").aisle("                                                               ").aisle("                                                               ").aisle(" P           P   P           P   P           P   P           P ")
                .aisle("FFFFFFFFFFFFFFFFFFFFFFFFFFFFFFFFFFFFFFFFFFFFFFFFFFFFFFFFFFFFFFF").aisle("FFFFFFFFFFFFFFFFFFFFFFFFFFFFFFFFFFFFFFFFFFFFFFFFFFFFFFFFFFFFFFF").aisle("CCCCCCCCCCCCCCCCCCCCCCCCCCCCCCCCCCCCCCCCCCCCCCCCCCCCCCCCCCCCCCC").aisle("                                                               ").aisle("                                                               ").aisle("                                                               ").aisle("                                                               ").aisle("                                                               ").aisle("                                                               ").aisle("                                                               ").aisle("                                                               ").aisle("                                                               ").aisle("                                                               ").aisle("                                                               ").aisle("                                                               ").aisle(" P           P   P           P   P           P   P           P ")
                .aisle("FFFFFFFFFFFFFFFFFFFFFFFFFFFFFFFFFFFFFFFFFFFFFFFFFFFFFFFFFFFFFFF").aisle("FFFFFFFFFFFFFFFFFFFFFFFFFFFFFFFFFFFFFFFFFFFFFFFFFFFFFFFFFFFFFFF").aisle("CCCCCCCCCCCCCCCCCCCCCCCCCCCCCCCCCCCCCCCCCCCCCCCCCCCCCCCCCCCCCCC").aisle("                                                               ").aisle("                                                               ").aisle("                                                               ").aisle("                                                               ").aisle("                                                               ").aisle("                                                               ").aisle("                                                               ").aisle("                                                               ").aisle("                                                               ").aisle("                                                               ").aisle("                                                               ").aisle("                                                               ").aisle(" P           P   P           P   P           P   P           P ")
                .aisle("FFFFFFFFFFFFFFFFFFFFFFFFFFFFFFFFFFFFFFFFFFFFFFFFFFFFFFFFFFFFFFF").aisle("FFFFFFFFFFFFFFFFFFFFFFFFFFFFFFFFFFFFFFFFFFFFFFFFFFFFFFFFFFFFFFF").aisle("CCCCCCCCCCCCCCCCCCCCCCCCCCCCCCCCCCCCCCCCCCCCCCCCCCCCCCCCCCCCCCC").aisle("CCCCCCCCCCCCCCCCCCCCCCCCCCCCCCCCCCCCCCCCCCCCCCCCCCCCCCCCCCCCCCC").aisle("CCCCCCCCCCCCCCCCCCCCCCCCCCCCCCCCCCCCCCCCCCCCCCCCCCCCCCCCCCCCCCC").aisle(" P   P   P   P   P   P   P   P   P   P   P   P   P   P   P   P ").aisle(" P   P   P   P   P   P   P   P   P   P   P   P   P   P   P   P ").aisle(" P   P   P   P   P   P   P   P   P   P   P   P   P   P   P   P ").aisle(" P   P   P   P   P   P   P   P   P   P   P   P   P   P   P   P ").aisle(" P   P   P   P   P   P   P   P   P   P   P   P   P   P   P   P ").aisle(" P   P   P   P   P   P   P   P   P   P   P   P   P   P   P   P ").aisle(" P   P   P   P   P   P   P   P   P   P   P   P   P   P   P   P ").aisle(" P   P   P   P   P   P   P   P   P   P   P   P   P   P   P   P ").aisle(" P   P   P   P   P   P   P   P   P   P   P   P   P   P   P   P ").aisle(" P   P   P   P   P   P   P   P   P   P   P   P   P   P   P   P ").aisle(" P   P   P   P   P   P   P   P   P   P   P   P   P   P   P   P ")
                .aisle("FFFFFFFFFFFFFFFFFFFFFFFFFFFFFFFFFFFFFFFFFFFFFFFFFFFFFFFFFFFFFFF").aisle("FFFFFFFFFFFFFFFFFFFFFFFFFFFFFFFFFFFFFFFFFFFFFFFFFFFFFFFFFFFFFFF").aisle("CCCCCCCCCCCCCCCCCCCCCCCCCCCCCCCCCCCCCCCCCCCCCCCCCCCCCCCCCCCCCCC").aisle("CCCCCCCCCCCCCCCCCCCCCCCCCCCCCCCCCCCCCCCCCCCCCCCCCCCCCCCCCCCCCCC").aisle("CCCCCCCCCCCCCCCCCCCCCCCCCCCCCCCCCCCCCCCCCCCCCCCCCCCCCCCCCCCCCCC").aisle("                                                               ").aisle("                                                               ").aisle("                                                               ").aisle("                                                               ").aisle("                                                               ").aisle("                                                               ").aisle("                                                               ").aisle("                                                               ").aisle("                                                               ").aisle("                                                               ").aisle("                                                               ")
                .where(' ', any())
                .where('F', states(SuSyBlocks.ROCKET_ASSEMBLER_CASING.getState(BlockRocketAssemblerCasing.RocketAssemblerCasingType.REINFORCED_FOUNDATION)))
                .where('C', states(SuSyBlocks.ROCKET_ASSEMBLER_CASING.getState(BlockRocketAssemblerCasing.RocketAssemblerCasingType.FOUNDATION)))
                .where('R', SuSyPredicates.rails())
                .where('P', states(SuSyBlocks.ROCKET_ASSEMBLER_CASING.getState(BlockRocketAssemblerCasing.RocketAssemblerCasingType.STRUCTURAL_FRAME)))
                .where('B', states(SuSyBlocks.ROCKET_ASSEMBLER_CASING.getState(BlockRocketAssemblerCasing.RocketAssemblerCasingType.RAILS)))
                .build();
    }

    @Override
    public ICubeRenderer getBaseTexture(IMultiblockPart iMultiblockPart) {
        return null;
    }

    @Override
    public MetaTileEntity createMetaTileEntity(IGregTechTileEntity iGregTechTileEntity) {
        return null;
    }
}
